<?xml version="1.0"?>
<robot name ="turtle">
  
  <!-- <link name="world"/> -->

  <link name="link_0">
    <inertial>
      <mass value ="100"/>
      <inertia ixx ="0.166667" ixy="0" ixz="0" iyy="0.166667" iyz="0" izz="0.166667" />
      <origin xyz="0 0 0" rpy="0 0 0" />
    </inertial>
    <!--
  <origin xyz="-0.04435 0.770245 0.0325" rpy="1.5707 0 0"/>
  !-->
  <visual name="visual_0">
      <origin xyz="0 0 0" rpy="0 0 0"/>
      <geometry>
        <box size="0.137 0.137 0.14"/>
      </geometry>
      <material name="orange"/>
<!--         <color rgba="0 0.5 1.0 1.0"/>
      </material>-->
    </visual>


      <collision name="collision_0">
        <origin xyz="0 0 0" rpy="0 0 0"/>
        <geometry>
          <box size="0.137 0.137 0.14"/>
        </geometry>
      </collision>
    </link>

    <gazebo reference="link_0">
      <gravity>1</gravity>
      <selfCollide>1</selfCollide>
      <mu1>1</mu1>
      <mu2>1</mu2>
      <fdir1>0 0 0</fdir1>
      <maxVel>0.01</maxVel>
      <minDepth>0</minDepth>
      <laserRetro>0</laserRetro>
      <maxContacts>10</maxContacts>
      <kp>1e+13</kp>
      <kd>1</kd>
    </gazebo>



  <link name="link_1">
    <inertial>
      <mass value ="0.25"/>
      <inertia ixx ="0.1" ixy="0" ixz="0" iyy="0.1" iyz="0" izz="0.1" />
      <origin xyz="0 0 0" rpy="0 0 0"/>
    </inertial>

    <!-- <origin xyz="-0.04435 0.770245 0.0325" rpy="1.5707 0 1e-06"/> -->

    <visual name="visual_1">
      <origin xyz="0 0 0" rpy="0 0 0"/>
      <!-- <origin xyz="-0.00315 0.0793 -0.0475" rpy="1.507 1.5707 0"/> -->
      <geometry>
          <cylinder radius="0.0325" length="0.018"/>
      </geometry>
      <material name="Cyan">
         <color rgba="0 1.0 1.0 1.0"/>
      </material>
    </visual>

    

    <collision name="collision_1">
      <origin xyz="0 0 0" rpy="0 0 0"/>
      <!-- <origin xyz="-0.00315 0.0793 -0.0475" rpy="1.507 1.5707 0"/> -->
      <geometry>
          <cylinder radius="0.0325" length="0.018"/>
      </geometry>
    </collision>
  </link>


  <gazebo reference="link_1">
      <gravity>1</gravity>
      <selfCollide>1</selfCollide>
      <mu1>1</mu1>
      <mu2>1</mu2>
      <fdir1>0 0 0</fdir1>
      <maxVel>0.01</maxVel>
      <minDepth>0</minDepth>
      <laserRetro>0</laserRetro>
      <maxContacts>10</maxContacts>
      <kp>1e+13</kp>
      <kd>1</kd>
   </gazebo>

  <joint name="link_0_JOINT_0" type="continuous">
      <parent link="link_0"/>
      <child link="link_1"/>
      <origin xyz="-0.0315 0.07885 -0.0475" rpy="1.5707 1.5707 0"/>
      <!-- <origin xyz="0 0 0" rpy="0 0 0"/> !-->
		<!-- 0.079 !-->
      <axis xyz="0 0 -1"/>
     <!-- <limit effort="-1" velocity="1"/> -->
      <dynamics damping="0" friction="0"/>
   </joint>



  <link name="link_1_clone">
    <inertial>
      <mass value ="0.25"/>
      <inertia ixx ="0.1001" ixy="0" ixz="0" iyy="0.1" iyz="0" izz="0.1" />
      <origin xyz="0 0 0" rpy="0 0 0"/>
    </inertial>
    <!--
    <origin xyz="-0.04435 0.612245 0.0325" rpy="1.5707 0 1e-06"/>
    -->
    <visual name="visual">
     <origin xyz="0 0 0" rpy="0 0 0"/>
     <!-- <origin xyz="-0.0315 -0.078875 -0.0475" rpy="1.5707 1.5707 0"/> !-->
      <geometry>
          <cylinder radius="0.0325" length="0.018"/>
      </geometry>
      <material name="Cyan">
         <color rgba="0 1.0 1.0 1.0"/>
      </material>
    </visual>

    

    <collision name="collision1">
    <origin xyz="0 0 0" rpy="0 0 0"/>
     <!--<origin xyz="-0.0315 -0.078875 -0.0475" rpy="1.5707 1.5707 0"/> -->
      <geometry>
          <cylinder radius="0.0325" length="0.018"/>
      </geometry>
    </collision>
  </link>

    <gazebo reference="link_1_clone">
      <gravity>1</gravity>
      <selfCollide>1</selfCollide>
      <mu1>1</mu1>
      <mu2>1</mu2>
      <fdir1>0 0 0</fdir1>
      <maxVel>0.01</maxVel>
      <minDepth>0</minDepth>
      <laserRetro>0</laserRetro>
      <maxContacts>10</maxContacts>
      <kp>1e+13</kp>
      <kd>1</kd>
    </gazebo>

    <joint name="link_0_JOINT_0_0" type="continuous">
      <parent link="link_0"/>
      <child link="link_1_clone"/>
      <origin xyz="-0.0315 -0.07885 -0.0475" rpy="1.5707 1.5707 0"/>
      <!-- <origin xyz="0 0 0" rpy="0 0 0"/> !-->

      <axis xyz="0 0 -1"/>
      <!-- <limit lower="1.79769e+308"upper="1.79769e+308" effort="-1" velocity="-1"/> !-->
      <dynamics damping="0" friction="0"/>
   </joint>



  <link name="link_2">
    <inertial>
      <mass value ="0.01"/>
      <inertia ixx ="0.1" ixy="0" ixz="0" iyy="0.1" iyz="0" izz="0.1" />
      <origin xyz="0 0 0" rpy="0 0 0"/>
    </inertial>
    <!--
    <origin xyz="0.03565 0.69112 0.005" rpy="0 0 0"/>
    !-->
    <visual name="visual">
      <origin xyz="0 0 0" rpy="0 0 0"/>
      <geometry>
        <sphere radius="0.005"/>
      </geometry>
      <material name="Cyan">
         <color rgba="0 1 1 1"/>
      </material>
    </visual>


    <collision name="collision">
      <origin xyz="0 0 0" rpy="0 0 0"/>
      <geometry>
        <sphere radius="0.005"/>
      </geometry>
    </collision>
  </link>

  <gazebo reference="link_2">
        <gravity>1</gravity>
        <selfCollide>1</selfCollide>
        <mu1>1</mu1>
        <mu2>1</mu2>
        <fdir1>0 0 0</fdir1>
        <maxVel>0.01</maxVel>
        <minDepth>0</minDepth>
        <laserRetro>0</laserRetro>
        <maxContacts>10</maxContacts>
        <kp>1e+13</kp>
        <kd>1</kd>
    </gazebo>

  <joint name="link_0_JOINT_2" type="continuous">
      <parent link="link_0"/>
      <child link="link_2"/>
      <origin xyz="0.055 0 -0.075" rpy="0 0 0"/>

      <axis xyz="1 1 1"/>
      <!-- <limit effort="-1" velocity="-1"/> !-->
      <dynamics damping="0" friction="0"/>
   </joint>



  <link name="link_LIDAR">
    <inertial>
      <mass value ="0.2"/>
      <inertia ixx ="4.15e-06" ixy="0" ixz="0" iyy="2.407e-06" iyz="0" izz="2.407e-06" />
      <origin xyz="0 0 0" rpy="0 0 0"/>
    </inertial>
    <!--
    <origin xyz="-0.030556 0.68938 0.172375" rpy="0 0 -1.5735"/>
    -->
    <visual name="visual_LIDAR">
      <origin xyz="0 0 0" rpy="0 0 0"/>
      <geometry>
        <box size="0.065 0.095 0.047"/>
      </geometry>
      <material name="Cyan">
         <color rgba="0 1.0 1.0 1.0"/>
      </material>
      </visual>


      <collision name="collision_LIDAR">
        <origin xyz="0 0 0" rpy="0 0 0"/>
        <geometry>
          <box size="0.065 0.095 0.047"/>
        </geometry>
      </collision>
    </link>

<!--
  <sensor name="LIDAR" update_rate="5.5">
    <parent link="link_LIDAR"/>
    <origin xyz="0 0 0" rpy="0 0 0"/>
    <ray>
      <horizontal samples="360" resolution="1" min_angle="-3.14" max_angle="3.14"/>
      <vertical samples="1" resolution="1" min_angle="0" max_angle="0"/>
    </ray>
  </sensor>
!-->

   <joint name="link_0_JOINT_0_1" type="fixed">
      <parent link="link_0"/>
      <child link="link_LIDAR"/>
      <origin xyz="-0.0201 -0.00174 0.09355" rpy="0 0 -1.5707"/>

      <limit effort="-1" velocity="-1"/>
      <dynamics damping="0" friction="0"/>
   </joint>

  <gazebo reference="link_LIDAR">
    <sensor type="gpu_ray" name="LIDAR">
      <visualize>true</visualize>
      <update_rate>5.5</update_rate>
      <ray>
        <scan>
          <horizontal>
            <samples>360</samples>
            <resolution>1</resolution>
            <min_angle>-3.14</min_angle>
            <max_angle>3.14</max_angle>
          </horizontal>
        </scan>

        <range>
          <min>0.15</min>
          <max>6</max>
          <resolution>0.05</resolution>
        </range>

        <noise>
          <type>gaussian</type>
          <!-- Noise parameters based on published spec for Hokuyo laser
               achieving "+-30mm" accuracy at range < 10m.  A mean of 0.0m and
               stddev of 0.01m will put 99.7% of samples within 0.03m of the true
               reading. -->
          <mean>0.0</mean>
          <stddev>0.01</stddev>
        </noise>
      </ray>

      <plugin name="gazebo_ros_LIDAR" filename="libgazebo_ros_gpu_laser.so">
        <topicName>/turtle/laser/scan</topicName>
        <frameName>link_LIDAR</frameName>
      </plugin>
    </sensor>
  </gazebo>

  <gazebo>
    <plugin name="differential_drive_controller" filename="libgazebo_ros_diff_drive.so">
      <alwaysOn>true</alwaysOn>
      <updateRate>100</updateRate>
      <leftJoint>link_0_JOINT_0_0</leftJoint>
      <rightJoint>link_0_JOINT_0</rightJoint>
      <wheelSeparation>0.158</wheelSeparation>
      <wheelDiameter>0.0650</wheelDiameter>
      <torque>1</torque>
      <commandTopic>cmd_vel</commandTopic>
      <odometryTopic>odom</odometryTopic>
      <odometryFrame>odom</odometryFrame>
      <robotBaseFrame>link_0</robotBaseFrame>
      <legacyMode>true</legacyMode>
    </plugin>
  </gazebo>

<!--
  <gazebo>
    <plugin name="skid_steer_drive_controller" filename="libgazebo_ros_skid_steer_drive.so">
      <updateRate>100.0</updateRate>
      <robotNamespace>/turtle</robotNamespace>
      <leftFrontJoint>link_0_JOINT_0</leftFrontJoint>
      <rightFrontJoint>link_0_JOINT_0_0</rightFrontJoint>
      <wheelSeparation>0.158</wheelSeparation>
      <wheelDiameter>0.13</wheelDiameter>
      <robotBaseFrame>link_0</robotBaseFrame>
      <torque>0.1</torque>
      <topicName>cmd_vel</topicName>
      <broadcastTF>false</broadcastTF>
    </plugin>
  </gazebo>
!-->
<!--
  <transmission name="tran_1">
    <type>transmission_interface/SimpleTransmission</type>
    <joint name="link_0_JOINT_0">
      <hardwareInterface>EffortJointInterface</hardwareInterface>
    </joint>

    <actuator name="motor1">
      <hardwareInterface>EffortJointInterface</hardwareInterface>
      <mechanicalReduction>1</mechanicalReduction>
    </actuator>
  </transmission>

    <transmission name="tran_1_clone">
      <type>transmission_interface/SimpleTransmission</type>
      <joint name="link_0_JOINT_0_0">
        <hardwareInterface>EffortJointInterface</hardwareInterface>
      </joint>

      <actuator name="motor1_clone">
        <hardwareInterface>EffortJointInterface</hardwareInterface>
        <mechanicalReduction>1</mechanicalReduction>
      </actuator>
    </transmission>

  <transmission name="tran_2">
    <type>transmission_interface/SimpleTransmission</type>
    <joint name="link_0_JOINT_2">
      <hardwareInterface>EffortJointInterface</hardwareInterface>
    </joint>

    <actuator name="motor2">
      <hardwareInterface>EffortJointInterface</hardwareInterface>
      <mechanicalReduction>1</mechanicalReduction>
    </actuator>
  </transmission>
-->

</robot>
    
